5:return {{["x"] = 0, ["y"] = 15, ["z"] = 3, ["name"] = "wool:white"}, {["x"] = 0, ["y"] = 15, ["z"] = 12, ["name"] = "wool:white"}, {["x"] = 1, ["y"] = 2, ["z"] = 2, ["name"] = "default:wood"}, {["x"] = 1, ["y"] = 2, ["z"] = 3, ["name"] = "default:wood"}, {["x"] = 1, ["y"] = 2, ["z"] = 4, ["name"] = "default:wood"}, {["x"] = 1, ["y"] = 2, ["z"] = 5, ["name"] = "default:wood"}, {["x"] = 1, ["y"] = 2, ["z"] = 10, ["name"] = "default:wood"}, {["x"] = 1, ["y"] = 2, ["z"] = 11, ["name"] = "default:wood"}, {["x"] = 1, ["y"] = 2, ["z"] = 12, ["name"] = "default:wood"}, {["x"] = 1, ["y"] = 2, ["z"] = 13, ["name"] = "default:wood"}, {["x"] = 1, ["y"] = 10, ["z"] = 3, ["name"] = "wool:white"}, {["x"] = 1, ["y"] = 10, ["z"] = 12, ["name"] = "wool:white"}, {["x"] = 1, ["y"] = 11, ["z"] = 3, ["name"] = "wool:white"}, {["x"] = 1, ["y"] = 11, ["z"] = 12, ["name"] = "wool:white"}, {["x"] = 1, ["y"] = 12, ["z"] = 3, ["name"] = "wool:white"}, {["x"] = 1, ["y"] = 12, ["z"] = 12, ["name"] = "wool:white"}, {["x"] = 1, ["y"] = 13, ["z"] = 3, ["name"] = "wool:white"}, {["x"] = 1, ["y"] = 13, ["z"] = 12, ["name"] = "wool:white"}, {["x"] = 1, ["y"] = 14, ["z"] = 3, ["name"] = "wool:white"}, {["x"] = 1, ["y"] = 14, ["z"] = 12, ["name"] = "wool:white"}, {["x"] = 1, ["y"] = 15, ["z"] = 0, ["name"] = "wool:white"}, {["x"] = 1, ["y"] = 15, ["z"] = 1, ["name"] = "wool:white"}, {["x"] = 1, ["y"] = 15, ["z"] = 2, ["name"] = "wool:white"}, {["x"] = 1, ["y"] = 15, ["z"] = 3, ["name"] = "wool:white"}, {["x"] = 1, ["y"] = 15, ["z"] = 4, ["name"] = "wool:white"}, {["x"] = 1, ["y"] = 15, ["z"] = 5, ["name"] = "wool:white"}, {["x"] = 1, ["y"] = 15, ["z"] = 6, ["name"] = "wool:white"}, {["x"] = 1, ["y"] = 15, ["z"] = 7, ["name"] = "wool:white"}, {["x"] = 1, ["y"] = 15, ["z"] = 8, ["name"] = "wool:white"}, {["x"] = 1, ["y"] = 15, ["z"] = 9, ["name"] = "wool:white"}, {["x"] = 1, ["y"] = 15, ["z"] = 10, ["name"] = "wool:white"}, {["x"] = 1, ["y"] = 15, ["z"] = 11, ["name"] = "wool:white"}, {["x"] = 1, ["y"] = 15, ["z"] = 12, ["name"] = "wool:white"}, {["x"] = 1, ["y"] = 15, ["z"] = 13, ["name"] = "wool:white"}, {["x"] = 1, ["y"] = 15, ["z"] = 14, ["name"] = "wool:white"}, {["x"] = 1, ["y"] = 15, ["z"] = 15, ["name"] = "wool:white"}, {["x"] = 2, ["y"] = 2, ["z"] = 2, ["name"] = "default:wood"}, {["x"] = 2, ["y"] = 2, ["z"] = 3, ["name"] = "default:wood"}, {["x"] = 2, ["y"] = 2, ["z"] = 4, ["name"] = "default:wood"}, {["x"] = 2, ["y"] = 2, ["z"] = 5, ["name"] = "default:wood"}, {["x"] = 2, ["y"] = 2, ["z"] = 10, ["name"] = "default:wood"}, {["x"] = 2, ["y"] = 2, ["z"] = 11, ["name"] = "default:wood"}, {["x"] = 2, ["y"] = 2, ["z"] = 12, ["name"] = "default:wood"}, {["x"] = 2, ["y"] = 2, ["z"] = 13, ["name"] = "default:wood"}, {["x"] = 2, ["y"] = 4, ["z"] = 3, ["name"] = "wool:white"}, {["x"] = 2, ["y"] = 4, ["z"] = 12, ["name"] = "wool:white"}, {["x"] = 2, ["y"] = 5, ["z"] = 3, ["name"] = "wool:white"}, {["x"] = 2, ["y"] = 5, ["z"] = 12, ["name"] = "wool:white"}, {["x"] = 2, ["y"] = 6, ["z"] = 3, ["name"] = "wool:white"}, {["x"] = 2, ["y"] = 6, ["z"] = 12, ["name"] = "wool:white"}, {["x"] = 2, ["y"] = 7, ["z"] = 3, ["name"] = "wool:white"}, {["x"] = 2, ["y"] = 7, ["z"] = 12, ["name"] = "wool:white"}, {["x"] = 2, ["y"] = 8, ["z"] = 3, ["name"] = "wool:white"}, {["x"] = 2, ["y"] = 8, ["z"] = 12, ["name"] = "wool:white"}, {["x"] = 2, ["y"] = 9, ["z"] = 3, ["name"] = "wool:white"}, {["x"] = 2, ["y"] = 9, ["z"] = 12, ["name"] = "wool:white"}, {["x"] = 2, ["y"] = 15, ["z"] = 3, ["name"] = "wool:white"}, {["x"] = 2, ["y"] = 15, ["z"] = 12, ["name"] = "wool:white"}, {["x"] = 3, ["y"] = 1, ["z"] = 3, ["name"] = "wool:white"}, {["x"] = 3, ["y"] = 1, ["z"] = 4, ["name"] = "wool:white"}, {["x"] = 3, ["y"] = 1, ["z"] = 11, ["name"] = "wool:white"}, {["x"] = 3, ["y"] = 1, ["z"] = 12, ["name"] = "wool:white"}, {["x"] = 3, ["y"] = 2, ["z"] = 0, ["name"] = "wool:white"}, {["x"] = 3, ["y"] = 2, ["z"] = 1, ["name"] = "wool:white"}, {["x"] = 3, ["y"] = 2, ["z"] = 2, ["name"] = "wool:white"}, {["x"] = 3, ["y"] = 2, ["z"] = 3, ["name"] = "default:wood"}, {["x"] = 3, ["y"] = 2, ["z"] = 4, ["name"] = "default:wood"}, {["x"] = 3, ["y"] = 2, ["z"] = 5, ["name"] = "wool:white"}, {["x"] = 3, ["y"] = 2, ["z"] = 6, ["name"] = "wool:white"}, {["x"] = 3, ["y"] = 2, ["z"] = 7, ["name"] = "wool:white"}, {["x"] = 3, ["y"] = 2, ["z"] = 8, ["name"] = "wool:white"}, {["x"] = 3, ["y"] = 2, ["z"] = 9, ["name"] = "wool:white"}, {["x"] = 3, ["y"] = 2, ["z"] = 10, ["name"] = "wool:white"}, {["x"] = 3, ["y"] = 2, ["z"] = 11, ["name"] = "default:wood"}, {["x"] = 3, ["y"] = 2, ["z"] = 12, ["name"] = "default:wood"}, {["x"] = 3, ["y"] = 2, ["z"] = 13, ["name"] = "wool:white"}, {["x"] = 3, ["y"] = 2, ["z"] = 14, ["name"] = "wool:white"}, {["x"] = 3, ["y"] = 2, ["z"] = 15, ["name"] = "wool:white"}, {["x"] = 3, ["y"] = 3, ["z"] = 3, ["name"] = "wool:white"}, {["x"] = 3, ["y"] = 3, ["z"] = 4, ["name"] = "wool:white"}, {["x"] = 3, ["y"] = 3, ["z"] = 11, ["name"] = "wool:white"}, {["x"] = 3, ["y"] = 3, ["z"] = 12, ["name"] = "wool:white"}, {["x"] = 4, ["y"] = 2, ["z"] = 2, ["name"] = "default:wood"}, {["x"] = 4, ["y"] = 2, ["z"] = 3, ["name"] = "default:wood"}, {["x"] = 4, ["y"] = 2, ["z"] = 4, ["name"] = "default:wood"}, {["x"] = 4, ["y"] = 2, ["z"] = 5, ["name"] = "default:wood"}, {["x"] = 4, ["y"] = 2, ["z"] = 10, ["name"] = "default:wood"}, {["x"] = 4, ["y"] = 2, ["z"] = 11, ["name"] = "default:wood"}, {["x"] = 4, ["y"] = 2, ["z"] = 12, ["name"] = "default:wood"}, {["x"] = 4, ["y"] = 2, ["z"] = 13, ["name"] = "default:wood"}, {["x"] = 5, ["y"] = 2, ["z"] = 2, ["name"] = "default:wood"}, {["x"] = 5, ["y"] = 2, ["z"] = 3, ["name"] = "default:wood"}, {["x"] = 5, ["y"] = 2, ["z"] = 4, ["name"] = "default:wood"}, {["x"] = 5, ["y"] = 2, ["z"] = 5, ["name"] = "default:wood"}, {["x"] = 5, ["y"] = 2, ["z"] = 10, ["name"] = "default:wood"}, {["x"] = 5, ["y"] = 2, ["z"] = 11, ["name"] = "default:wood"}, {["x"] = 5, ["y"] = 2, ["z"] = 12, ["name"] = "default:wood"}, {["x"] = 5, ["y"] = 2, ["z"] = 13, ["name"] = "default:wood"}, {["x"] = 6, ["y"] = 2, ["z"] = 2, ["name"] = "default:wood"}, {["x"] = 6, ["y"] = 2, ["z"] = 3, ["name"] = "default:wood"}, {["x"] = 6, ["y"] = 2, ["z"] = 4, ["name"] = "default:wood"}, {["x"] = 6, ["y"] = 2, ["z"] = 5, ["name"] = "default:wood"}, {["x"] = 6, ["y"] = 2, ["z"] = 10, ["name"] = "default:wood"}, {["x"] = 6, ["y"] = 2, ["z"] = 11, ["name"] = "default:wood"}, {["x"] = 6, ["y"] = 2, ["z"] = 12, ["name"] = "default:wood"}, {["x"] = 6, ["y"] = 2, ["z"] = 13, ["name"] = "default:wood"}, {["x"] = 7, ["y"] = 2, ["z"] = 2, ["name"] = "default:wood"}, {["x"] = 7, ["y"] = 2, ["z"] = 3, ["name"] = "default:wood"}, {["x"] = 7, ["y"] = 2, ["z"] = 4, ["name"] = "default:wood"}, {["x"] = 7, ["y"] = 2, ["z"] = 5, ["name"] = "default:wood"}, {["x"] = 7, ["y"] = 2, ["z"] = 10, ["name"] = "default:wood"}, {["x"] = 7, ["y"] = 2, ["z"] = 11, ["name"] = "default:wood"}, {["x"] = 7, ["y"] = 2, ["z"] = 12, ["name"] = "default:wood"}, {["x"] = 7, ["y"] = 2, ["z"] = 13, ["name"] = "default:wood"}, {["x"] = 8, ["y"] = 2, ["z"] = 2, ["name"] = "default:wood"}, {["x"] = 8, ["y"] = 2, ["z"] = 3, ["name"] = "default:wood"}, {["x"] = 8, ["y"] = 2, ["z"] = 4, ["name"] = "default:wood"}, {["x"] = 8, ["y"] = 2, ["z"] = 5, ["name"] = "default:wood"}, {["x"] = 8, ["y"] = 2, ["z"] = 10, ["name"] = "default:wood"}, {["x"] = 8, ["y"] = 2, ["z"] = 11, ["name"] = "default:wood"}, {["x"] = 8, ["y"] = 2, ["z"] = 12, ["name"] = "default:wood"}, {["x"] = 8, ["y"] = 2, ["z"] = 13, ["name"] = "default:wood"}, {["x"] = 9, ["y"] = 2, ["z"] = 2, ["name"] = "default:wood"}, {["x"] = 9, ["y"] = 2, ["z"] = 3, ["name"] = "default:wood"}, {["x"] = 9, ["y"] = 2, ["z"] = 4, ["name"] = "default:wood"}, {["x"] = 9, ["y"] = 2, ["z"] = 5, ["name"] = "default:wood"}, {["x"] = 9, ["y"] = 2, ["z"] = 10, ["name"] = "default:wood"}, {["x"] = 9, ["y"] = 2, ["z"] = 11, ["name"] = "default:wood"}, {["x"] = 9, ["y"] = 2, ["z"] = 12, ["name"] = "default:wood"}, {["x"] = 9, ["y"] = 2, ["z"] = 13, ["name"] = "default:wood"}, {["x"] = 10, ["y"] = 2, ["z"] = 2, ["name"] = "default:wood"}, {["x"] = 10, ["y"] = 2, ["z"] = 3, ["name"] = "default:wood"}, {["x"] = 10, ["y"] = 2, ["z"] = 4, ["name"] = "default:wood"}, {["x"] = 10, ["y"] = 2, ["z"] = 5, ["name"] = "default:wood"}, {["x"] = 10, ["y"] = 2, ["z"] = 10, ["name"] = "default:wood"}, {["x"] = 10, ["y"] = 2, ["z"] = 11, ["name"] = "default:wood"}, {["x"] = 10, ["y"] = 2, ["z"] = 12, ["name"] = "default:wood"}, {["x"] = 10, ["y"] = 2, ["z"] = 13, ["name"] = "default:wood"}, {["x"] = 11, ["y"] = 2, ["z"] = 2, ["name"] = "default:wood"}, {["x"] = 11, ["y"] = 2, ["z"] = 3, ["name"] = "default:wood"}, {["x"] = 11, ["y"] = 2, ["z"] = 4, ["name"] = "default:wood"}, {["x"] = 11, ["y"] = 2, ["z"] = 5, ["name"] = "default:wood"}, {["x"] = 11, ["y"] = 2, ["z"] = 10, ["name"] = "default:wood"}, {["x"] = 11, ["y"] = 2, ["z"] = 11, ["name"] = "default:wood"}, {["x"] = 11, ["y"] = 2, ["z"] = 12, ["name"] = "default:wood"}, {["x"] = 11, ["y"] = 2, ["z"] = 13, ["name"] = "default:wood"}, {["x"] = 12, ["y"] = 1, ["z"] = 3, ["name"] = "wool:white"}, {["x"] = 12, ["y"] = 1, ["z"] = 4, ["name"] = "wool:white"}, {["x"] = 12, ["y"] = 1, ["z"] = 11, ["name"] = "wool:white"}, {["x"] = 12, ["y"] = 1, ["z"] = 12, ["name"] = "wool:white"}, {["x"] = 12, ["y"] = 2, ["z"] = 0, ["name"] = "wool:white"}, {["x"] = 12, ["y"] = 2, ["z"] = 1, ["name"] = "wool:white"}, {["x"] = 12, ["y"] = 2, ["z"] = 2, ["name"] = "wool:white"}, {["x"] = 12, ["y"] = 2, ["z"] = 3, ["name"] = "default:wood"}, {["x"] = 12, ["y"] = 2, ["z"] = 4, ["name"] = "default:wood"}, {["x"] = 12, ["y"] = 2, ["z"] = 5, ["name"] = "wool:white"}, {["x"] = 12, ["y"] = 2, ["z"] = 6, ["name"] = "wool:white"}, {["x"] = 12, ["y"] = 2, ["z"] = 7, ["name"] = "wool:white"}, {["x"] = 12, ["y"] = 2, ["z"] = 8, ["name"] = "wool:white"}, {["x"] = 12, ["y"] = 2, ["z"] = 9, ["name"] = "wool:white"}, {["x"] = 12, ["y"] = 2, ["z"] = 10, ["name"] = "wool:white"}, {["x"] = 12, ["y"] = 2, ["z"] = 11, ["name"] = "default:wood"}, {["x"] = 12, ["y"] = 2, ["z"] = 12, ["name"] = "default:wood"}, {["x"] = 12, ["y"] = 2, ["z"] = 13, ["name"] = "wool:white"}, {["x"] = 12, ["y"] = 2, ["z"] = 14, ["name"] = "wool:white"}, {["x"] = 12, ["y"] = 2, ["z"] = 15, ["name"] = "wool:white"}, {["x"] = 12, ["y"] = 3, ["z"] = 3, ["name"] = "wool:white"}, {["x"] = 12, ["y"] = 3, ["z"] = 4, ["name"] = "wool:white"}, {["x"] = 12, ["y"] = 3, ["z"] = 11, ["name"] = "wool:white"}, {["x"] = 12, ["y"] = 3, ["z"] = 12, ["name"] = "wool:white"}, {["x"] = 13, ["y"] = 2, ["z"] = 2, ["name"] = "default:wood"}, {["x"] = 13, ["y"] = 2, ["z"] = 3, ["name"] = "default:wood"}, {["x"] = 13, ["y"] = 2, ["z"] = 4, ["name"] = "default:wood"}, {["x"] = 13, ["y"] = 2, ["z"] = 5, ["name"] = "default:wood"}, {["x"] = 13, ["y"] = 2, ["z"] = 10, ["name"] = "default:wood"}, {["x"] = 13, ["y"] = 2, ["z"] = 11, ["name"] = "default:wood"}, {["x"] = 13, ["y"] = 2, ["z"] = 12, ["name"] = "default:wood"}, {["x"] = 13, ["y"] = 2, ["z"] = 13, ["name"] = "default:wood"}, {["x"] = 13, ["y"] = 4, ["z"] = 3, ["name"] = "wool:white"}, {["x"] = 13, ["y"] = 4, ["z"] = 12, ["name"] = "wool:white"}, {["x"] = 13, ["y"] = 5, ["z"] = 3, ["name"] = "wool:white"}, {["x"] = 13, ["y"] = 5, ["z"] = 12, ["name"] = "wool:white"}, {["x"] = 13, ["y"] = 6, ["z"] = 3, ["name"] = "wool:white"}, {["x"] = 13, ["y"] = 6, ["z"] = 12, ["name"] = "wool:white"}, {["x"] = 13, ["y"] = 7, ["z"] = 3, ["name"] = "wool:white"}, {["x"] = 13, ["y"] = 7, ["z"] = 12, ["name"] = "wool:white"}, {["x"] = 13, ["y"] = 8, ["z"] = 3, ["name"] = "wool:white"}, {["x"] = 13, ["y"] = 8, ["z"] = 12, ["name"] = "wool:white"}, {["x"] = 13, ["y"] = 9, ["z"] = 3, ["name"] = "wool:white"}, {["x"] = 13, ["y"] = 9, ["z"] = 12, ["name"] = "wool:white"}, {["x"] = 13, ["y"] = 15, ["z"] = 3, ["name"] = "wool:white"}, {["x"] = 13, ["y"] = 15, ["z"] = 12, ["name"] = "wool:white"}, {["x"] = 14, ["y"] = 2, ["z"] = 2, ["name"] = "default:wood"}, {["x"] = 14, ["y"] = 2, ["z"] = 3, ["name"] = "default:wood"}, {["x"] = 14, ["y"] = 2, ["z"] = 4, ["name"] = "default:wood"}, {["x"] = 14, ["y"] = 2, ["z"] = 5, ["name"] = "default:wood"}, {["x"] = 14, ["y"] = 2, ["z"] = 10, ["name"] = "default:wood"}, {["x"] = 14, ["y"] = 2, ["z"] = 11, ["name"] = "default:wood"}, {["x"] = 14, ["y"] = 2, ["z"] = 12, ["name"] = "default:wood"}, {["x"] = 14, ["y"] = 2, ["z"] = 13, ["name"] = "default:wood"}, {["x"] = 14, ["y"] = 10, ["z"] = 3, ["name"] = "wool:white"}, {["x"] = 14, ["y"] = 10, ["z"] = 12, ["name"] = "wool:white"}, {["x"] = 14, ["y"] = 11, ["z"] = 3, ["name"] = "wool:white"}, {["x"] = 14, ["y"] = 11, ["z"] = 12, ["name"] = "wool:white"}, {["x"] = 14, ["y"] = 12, ["z"] = 3, ["name"] = "wool:white"}, {["x"] = 14, ["y"] = 12, ["z"] = 12, ["name"] = "wool:white"}, {["x"] = 14, ["y"] = 13, ["z"] = 3, ["name"] = "wool:white"}, {["x"] = 14, ["y"] = 13, ["z"] = 12, ["name"] = "wool:white"}, {["x"] = 14, ["y"] = 14, ["z"] = 3, ["name"] = "wool:white"}, {["x"] = 14, ["y"] = 14, ["z"] = 12, ["name"] = "wool:white"}, {["x"] = 14, ["y"] = 15, ["z"] = 0, ["name"] = "wool:white"}, {["x"] = 14, ["y"] = 15, ["z"] = 1, ["name"] = "wool:white"}, {["x"] = 14, ["y"] = 15, ["z"] = 2, ["name"] = "wool:white"}, {["x"] = 14, ["y"] = 15, ["z"] = 3, ["name"] = "wool:white"}, {["x"] = 14, ["y"] = 15, ["z"] = 4, ["name"] = "wool:white"}, {["x"] = 14, ["y"] = 15, ["z"] = 5, ["name"] = "wool:white"}, {["x"] = 14, ["y"] = 15, ["z"] = 6, ["name"] = "wool:white"}, {["x"] = 14, ["y"] = 15, ["z"] = 7, ["name"] = "wool:white"}, {["x"] = 14, ["y"] = 15, ["z"] = 8, ["name"] = "wool:white"}, {["x"] = 14, ["y"] = 15, ["z"] = 9, ["name"] = "wool:white"}, {["x"] = 14, ["y"] = 15, ["z"] = 10, ["name"] = "wool:white"}, {["x"] = 14, ["y"] = 15, ["z"] = 11, ["name"] = "wool:white"}, {["x"] = 14, ["y"] = 15, ["z"] = 12, ["name"] = "wool:white"}, {["x"] = 14, ["y"] = 15, ["z"] = 13, ["name"] = "wool:white"}, {["x"] = 14, ["y"] = 15, ["z"] = 14, ["name"] = "wool:white"}, {["x"] = 14, ["y"] = 15, ["z"] = 15, ["name"] = "wool:white"}, {["x"] = 15, ["y"] = 15, ["z"] = 3, ["name"] = "wool:white"}, {["x"] = 15, ["y"] = 15, ["z"] = 12, ["name"] = "wool:white"}}