5:return {{["x"] = 0, ["y"] = 0, ["z"] = 3, ["name"] = "default:wood"}, {["x"] = 0, ["y"] = 0, ["z"] = 4, ["name"] = "default:wood"}, {["x"] = 0, ["y"] = 1, ["z"] = 3, ["name"] = "default:wood"}, {["x"] = 0, ["y"] = 1, ["z"] = 4, ["name"] = "default:wood"}, {["x"] = 0, ["y"] = 2, ["z"] = 3, ["name"] = "default:wood"}, {["x"] = 0, ["y"] = 2, ["z"] = 4, ["name"] = "default:wood"}, {["x"] = 0, ["y"] = 3, ["z"] = 3, ["name"] = "default:wood"}, {["x"] = 0, ["y"] = 3, ["z"] = 4, ["name"] = "default:wood"}, {["x"] = 0, ["y"] = 4, ["z"] = 3, ["name"] = "default:wood"}, {["x"] = 0, ["y"] = 4, ["z"] = 4, ["name"] = "default:wood"}, {["x"] = 0, ["y"] = 5, ["z"] = 3, ["name"] = "default:wood"}, {["x"] = 0, ["y"] = 5, ["z"] = 4, ["name"] = "default:wood"}, {["x"] = 0, ["y"] = 6, ["z"] = 3, ["name"] = "default:wood"}, {["x"] = 0, ["y"] = 6, ["z"] = 4, ["name"] = "default:wood"}, {["x"] = 0, ["y"] = 7, ["z"] = 3, ["name"] = "default:wood"}, {["x"] = 0, ["y"] = 7, ["z"] = 4, ["name"] = "default:wood"}, {["x"] = 1, ["y"] = 0, ["z"] = 2, ["name"] = "default:wood"}, {["x"] = 1, ["y"] = 0, ["z"] = 3, ["name"] = "default:wood"}, {["x"] = 1, ["y"] = 0, ["z"] = 4, ["name"] = "default:wood"}, {["x"] = 1, ["y"] = 0, ["z"] = 5, ["name"] = "default:wood"}, {["x"] = 1, ["y"] = 1, ["z"] = 2, ["name"] = "default:wood"}, {["x"] = 1, ["y"] = 1, ["z"] = 3, ["name"] = "default:wood"}, {["x"] = 1, ["y"] = 1, ["z"] = 4, ["name"] = "default:wood"}, {["x"] = 1, ["y"] = 1, ["z"] = 5, ["name"] = "default:wood"}, {["x"] = 1, ["y"] = 2, ["z"] = 2, ["name"] = "default:wood"}, {["x"] = 1, ["y"] = 2, ["z"] = 3, ["name"] = "default:wood"}, {["x"] = 1, ["y"] = 2, ["z"] = 4, ["name"] = "default:wood"}, {["x"] = 1, ["y"] = 2, ["z"] = 5, ["name"] = "default:wood"}, {["x"] = 1, ["y"] = 3, ["z"] = 2, ["name"] = "default:wood"}, {["x"] = 1, ["y"] = 3, ["z"] = 3, ["name"] = "default:wood"}, {["x"] = 1, ["y"] = 3, ["z"] = 4, ["name"] = "default:wood"}, {["x"] = 1, ["y"] = 3, ["z"] = 5, ["name"] = "default:wood"}, {["x"] = 1, ["y"] = 4, ["z"] = 2, ["name"] = "default:wood"}, {["x"] = 1, ["y"] = 4, ["z"] = 3, ["name"] = "default:wood"}, {["x"] = 1, ["y"] = 4, ["z"] = 4, ["name"] = "default:wood"}, {["x"] = 1, ["y"] = 4, ["z"] = 5, ["name"] = "default:wood"}, {["x"] = 1, ["y"] = 5, ["z"] = 2, ["name"] = "default:wood"}, {["x"] = 1, ["y"] = 5, ["z"] = 3, ["name"] = "default:wood"}, {["x"] = 1, ["y"] = 5, ["z"] = 4, ["name"] = "default:wood"}, {["x"] = 1, ["y"] = 5, ["z"] = 5, ["name"] = "default:wood"}, {["x"] = 1, ["y"] = 6, ["z"] = 2, ["name"] = "default:wood"}, {["x"] = 1, ["y"] = 6, ["z"] = 3, ["name"] = "default:wood"}, {["x"] = 1, ["y"] = 6, ["z"] = 4, ["name"] = "default:wood"}, {["x"] = 1, ["y"] = 6, ["z"] = 5, ["name"] = "default:wood"}, {["x"] = 1, ["y"] = 7, ["z"] = 2, ["name"] = "default:wood"}, {["x"] = 1, ["y"] = 7, ["z"] = 3, ["name"] = "default:wood"}, {["x"] = 1, ["y"] = 7, ["z"] = 4, ["name"] = "default:wood"}, {["x"] = 1, ["y"] = 7, ["z"] = 5, ["name"] = "default:wood"}, {["x"] = 2, ["y"] = 0, ["z"] = 2, ["name"] = "default:wood"}, {["x"] = 2, ["y"] = 0, ["z"] = 3, ["name"] = "default:wood"}, {["x"] = 2, ["y"] = 0, ["z"] = 4, ["name"] = "default:wood"}, {["x"] = 2, ["y"] = 0, ["z"] = 5, ["name"] = "default:wood"}, {["x"] = 2, ["y"] = 1, ["z"] = 2, ["name"] = "default:wood"}, {["x"] = 2, ["y"] = 1, ["z"] = 3, ["name"] = "default:wood"}, {["x"] = 2, ["y"] = 1, ["z"] = 4, ["name"] = "default:wood"}, {["x"] = 2, ["y"] = 1, ["z"] = 5, ["name"] = "default:wood"}, {["x"] = 2, ["y"] = 2, ["z"] = 2, ["name"] = "default:wood"}, {["x"] = 2, ["y"] = 2, ["z"] = 3, ["name"] = "default:wood"}, {["x"] = 2, ["y"] = 2, ["z"] = 4, ["name"] = "default:wood"}, {["x"] = 2, ["y"] = 2, ["z"] = 5, ["name"] = "default:wood"}, {["x"] = 2, ["y"] = 3, ["z"] = 2, ["name"] = "default:wood"}, {["x"] = 2, ["y"] = 3, ["z"] = 3, ["name"] = "default:wood"}, {["x"] = 2, ["y"] = 3, ["z"] = 4, ["name"] = "default:wood"}, {["x"] = 2, ["y"] = 3, ["z"] = 5, ["name"] = "default:wood"}, {["x"] = 2, ["y"] = 4, ["z"] = 2, ["name"] = "default:wood"}, {["x"] = 2, ["y"] = 4, ["z"] = 3, ["name"] = "default:wood"}, {["x"] = 2, ["y"] = 4, ["z"] = 4, ["name"] = "default:wood"}, {["x"] = 2, ["y"] = 4, ["z"] = 5, ["name"] = "default:wood"}, {["x"] = 2, ["y"] = 5, ["z"] = 2, ["name"] = "default:wood"}, {["x"] = 2, ["y"] = 5, ["z"] = 3, ["name"] = "default:wood"}, {["x"] = 2, ["y"] = 5, ["z"] = 4, ["name"] = "default:wood"}, {["x"] = 2, ["y"] = 5, ["z"] = 5, ["name"] = "default:wood"}, {["x"] = 2, ["y"] = 6, ["z"] = 2, ["name"] = "default:wood"}, {["x"] = 2, ["y"] = 6, ["z"] = 3, ["name"] = "default:wood"}, {["x"] = 2, ["y"] = 6, ["z"] = 4, ["name"] = "default:wood"}, {["x"] = 2, ["y"] = 6, ["z"] = 5, ["name"] = "default:wood"}, {["x"] = 2, ["y"] = 7, ["z"] = 2, ["name"] = "default:wood"}, {["x"] = 2, ["y"] = 7, ["z"] = 3, ["name"] = "default:wood"}, {["x"] = 2, ["y"] = 7, ["z"] = 4, ["name"] = "default:wood"}, {["x"] = 2, ["y"] = 7, ["z"] = 5, ["name"] = "default:wood"}, {["x"] = 3, ["y"] = 0, ["z"] = 3, ["name"] = "default:wood"}, {["x"] = 3, ["y"] = 0, ["z"] = 4, ["name"] = "default:wood"}, {["x"] = 3, ["y"] = 1, ["z"] = 3, ["name"] = "default:wood"}, {["x"] = 3, ["y"] = 1, ["z"] = 4, ["name"] = "default:wood"}, {["x"] = 3, ["y"] = 2, ["z"] = 3, ["name"] = "default:wood"}, {["x"] = 3, ["y"] = 2, ["z"] = 4, ["name"] = "default:wood"}, {["x"] = 3, ["y"] = 3, ["z"] = 3, ["name"] = "default:wood"}, {["x"] = 3, ["y"] = 3, ["z"] = 4, ["name"] = "default:wood"}, {["x"] = 3, ["y"] = 4, ["z"] = 3, ["name"] = "default:wood"}, {["x"] = 3, ["y"] = 4, ["z"] = 4, ["name"] = "default:wood"}, {["x"] = 3, ["y"] = 5, ["z"] = 3, ["name"] = "default:wood"}, {["x"] = 3, ["y"] = 5, ["z"] = 4, ["name"] = "default:wood"}, {["x"] = 3, ["y"] = 6, ["z"] = 3, ["name"] = "default:wood"}, {["x"] = 3, ["y"] = 6, ["z"] = 4, ["name"] = "default:wood"}, {["x"] = 3, ["y"] = 7, ["z"] = 3, ["name"] = "default:wood"}, {["x"] = 3, ["y"] = 7, ["z"] = 4, ["name"] = "default:wood"}, {["x"] = 12, ["y"] = 0, ["z"] = 3, ["name"] = "default:wood"}, {["x"] = 12, ["y"] = 0, ["z"] = 4, ["name"] = "default:wood"}, {["x"] = 12, ["y"] = 1, ["z"] = 3, ["name"] = "default:wood"}, {["x"] = 12, ["y"] = 1, ["z"] = 4, ["name"] = "default:wood"}, {["x"] = 12, ["y"] = 2, ["z"] = 3, ["name"] = "default:wood"}, {["x"] = 12, ["y"] = 2, ["z"] = 4, ["name"] = "default:wood"}, {["x"] = 12, ["y"] = 3, ["z"] = 3, ["name"] = "default:wood"}, {["x"] = 12, ["y"] = 3, ["z"] = 4, ["name"] = "default:wood"}, {["x"] = 12, ["y"] = 4, ["z"] = 3, ["name"] = "default:wood"}, {["x"] = 12, ["y"] = 4, ["z"] = 4, ["name"] = "default:wood"}, {["x"] = 12, ["y"] = 5, ["z"] = 3, ["name"] = "default:wood"}, {["x"] = 12, ["y"] = 5, ["z"] = 4, ["name"] = "default:wood"}, {["x"] = 12, ["y"] = 6, ["z"] = 3, ["name"] = "default:wood"}, {["x"] = 12, ["y"] = 6, ["z"] = 4, ["name"] = "default:wood"}, {["x"] = 12, ["y"] = 7, ["z"] = 3, ["name"] = "default:wood"}, {["x"] = 12, ["y"] = 7, ["z"] = 4, ["name"] = "default:wood"}, {["x"] = 13, ["y"] = 0, ["z"] = 2, ["name"] = "default:wood"}, {["x"] = 13, ["y"] = 0, ["z"] = 3, ["name"] = "default:wood"}, {["x"] = 13, ["y"] = 0, ["z"] = 4, ["name"] = "default:wood"}, {["x"] = 13, ["y"] = 0, ["z"] = 5, ["name"] = "default:wood"}, {["x"] = 13, ["y"] = 1, ["z"] = 2, ["name"] = "default:wood"}, {["x"] = 13, ["y"] = 1, ["z"] = 3, ["name"] = "default:wood"}, {["x"] = 13, ["y"] = 1, ["z"] = 4, ["name"] = "default:wood"}, {["x"] = 13, ["y"] = 1, ["z"] = 5, ["name"] = "default:wood"}, {["x"] = 13, ["y"] = 2, ["z"] = 2, ["name"] = "default:wood"}, {["x"] = 13, ["y"] = 2, ["z"] = 3, ["name"] = "default:wood"}, {["x"] = 13, ["y"] = 2, ["z"] = 4, ["name"] = "default:wood"}, {["x"] = 13, ["y"] = 2, ["z"] = 5, ["name"] = "default:wood"}, {["x"] = 13, ["y"] = 3, ["z"] = 2, ["name"] = "default:wood"}, {["x"] = 13, ["y"] = 3, ["z"] = 3, ["name"] = "default:wood"}, {["x"] = 13, ["y"] = 3, ["z"] = 4, ["name"] = "default:wood"}, {["x"] = 13, ["y"] = 3, ["z"] = 5, ["name"] = "default:wood"}, {["x"] = 13, ["y"] = 4, ["z"] = 2, ["name"] = "default:wood"}, {["x"] = 13, ["y"] = 4, ["z"] = 3, ["name"] = "default:wood"}, {["x"] = 13, ["y"] = 4, ["z"] = 4, ["name"] = "default:wood"}, {["x"] = 13, ["y"] = 4, ["z"] = 5, ["name"] = "default:wood"}, {["x"] = 13, ["y"] = 5, ["z"] = 2, ["name"] = "default:wood"}, {["x"] = 13, ["y"] = 5, ["z"] = 3, ["name"] = "default:wood"}, {["x"] = 13, ["y"] = 5, ["z"] = 4, ["name"] = "default:wood"}, {["x"] = 13, ["y"] = 5, ["z"] = 5, ["name"] = "default:wood"}, {["x"] = 13, ["y"] = 6, ["z"] = 2, ["name"] = "default:wood"}, {["x"] = 13, ["y"] = 6, ["z"] = 3, ["name"] = "default:wood"}, {["x"] = 13, ["y"] = 6, ["z"] = 4, ["name"] = "default:wood"}, {["x"] = 13, ["y"] = 6, ["z"] = 5, ["name"] = "default:wood"}, {["x"] = 13, ["y"] = 7, ["z"] = 2, ["name"] = "default:wood"}, {["x"] = 13, ["y"] = 7, ["z"] = 3, ["name"] = "default:wood"}, {["x"] = 13, ["y"] = 7, ["z"] = 4, ["name"] = "default:wood"}, {["x"] = 13, ["y"] = 7, ["z"] = 5, ["name"] = "default:wood"}, {["x"] = 14, ["y"] = 0, ["z"] = 2, ["name"] = "default:wood"}, {["x"] = 14, ["y"] = 0, ["z"] = 3, ["name"] = "default:wood"}, {["x"] = 14, ["y"] = 0, ["z"] = 4, ["name"] = "default:wood"}, {["x"] = 14, ["y"] = 0, ["z"] = 5, ["name"] = "default:wood"}, {["x"] = 14, ["y"] = 1, ["z"] = 2, ["name"] = "default:wood"}, {["x"] = 14, ["y"] = 1, ["z"] = 3, ["name"] = "default:wood"}, {["x"] = 14, ["y"] = 1, ["z"] = 4, ["name"] = "default:wood"}, {["x"] = 14, ["y"] = 1, ["z"] = 5, ["name"] = "default:wood"}, {["x"] = 14, ["y"] = 2, ["z"] = 2, ["name"] = "default:wood"}, {["x"] = 14, ["y"] = 2, ["z"] = 3, ["name"] = "default:wood"}, {["x"] = 14, ["y"] = 2, ["z"] = 4, ["name"] = "default:wood"}, {["x"] = 14, ["y"] = 2, ["z"] = 5, ["name"] = "default:wood"}, {["x"] = 14, ["y"] = 3, ["z"] = 2, ["name"] = "default:wood"}, {["x"] = 14, ["y"] = 3, ["z"] = 3, ["name"] = "default:wood"}, {["x"] = 14, ["y"] = 3, ["z"] = 4, ["name"] = "default:wood"}, {["x"] = 14, ["y"] = 3, ["z"] = 5, ["name"] = "default:wood"}, {["x"] = 14, ["y"] = 4, ["z"] = 2, ["name"] = "default:wood"}, {["x"] = 14, ["y"] = 4, ["z"] = 3, ["name"] = "default:wood"}, {["x"] = 14, ["y"] = 4, ["z"] = 4, ["name"] = "default:wood"}, {["x"] = 14, ["y"] = 4, ["z"] = 5, ["name"] = "default:wood"}, {["x"] = 14, ["y"] = 5, ["z"] = 2, ["name"] = "default:wood"}, {["x"] = 14, ["y"] = 5, ["z"] = 3, ["name"] = "default:wood"}, {["x"] = 14, ["y"] = 5, ["z"] = 4, ["name"] = "default:wood"}, {["x"] = 14, ["y"] = 5, ["z"] = 5, ["name"] = "default:wood"}, {["x"] = 14, ["y"] = 6, ["z"] = 2, ["name"] = "default:wood"}, {["x"] = 14, ["y"] = 6, ["z"] = 3, ["name"] = "default:wood"}, {["x"] = 14, ["y"] = 6, ["z"] = 4, ["name"] = "default:wood"}, {["x"] = 14, ["y"] = 6, ["z"] = 5, ["name"] = "default:wood"}, {["x"] = 14, ["y"] = 7, ["z"] = 2, ["name"] = "default:wood"}, {["x"] = 14, ["y"] = 7, ["z"] = 3, ["name"] = "default:wood"}, {["x"] = 14, ["y"] = 7, ["z"] = 4, ["name"] = "default:wood"}, {["x"] = 14, ["y"] = 7, ["z"] = 5, ["name"] = "default:wood"}, {["x"] = 15, ["y"] = 0, ["z"] = 3, ["name"] = "default:wood"}, {["x"] = 15, ["y"] = 0, ["z"] = 4, ["name"] = "default:wood"}, {["x"] = 15, ["y"] = 1, ["z"] = 3, ["name"] = "default:wood"}, {["x"] = 15, ["y"] = 1, ["z"] = 4, ["name"] = "default:wood"}, {["x"] = 15, ["y"] = 2, ["z"] = 3, ["name"] = "default:wood"}, {["x"] = 15, ["y"] = 2, ["z"] = 4, ["name"] = "default:wood"}, {["x"] = 15, ["y"] = 3, ["z"] = 3, ["name"] = "default:wood"}, {["x"] = 15, ["y"] = 3, ["z"] = 4, ["name"] = "default:wood"}, {["x"] = 15, ["y"] = 4, ["z"] = 3, ["name"] = "default:wood"}, {["x"] = 15, ["y"] = 4, ["z"] = 4, ["name"] = "default:wood"}, {["x"] = 15, ["y"] = 5, ["z"] = 3, ["name"] = "default:wood"}, {["x"] = 15, ["y"] = 5, ["z"] = 4, ["name"] = "default:wood"}, {["x"] = 15, ["y"] = 6, ["z"] = 3, ["name"] = "default:wood"}, {["x"] = 15, ["y"] = 6, ["z"] = 4, ["name"] = "default:wood"}, {["x"] = 15, ["y"] = 7, ["z"] = 3, ["name"] = "default:wood"}, {["x"] = 15, ["y"] = 7, ["z"] = 4, ["name"] = "default:wood"}}