5:return {{["x"] = 0, ["y"] = 15, ["param1"] = 76, ["z"] = 12, ["name"] = "wool:white"}, {["x"] = 0, ["meta"] = {["fields"] = {}, ["inventory"] = {}}, ["y"] = 16, ["param1"] = 76, ["z"] = 3, ["name"] = "wool:white"}, {["x"] = 1, ["y"] = 2, ["param1"] = 56, ["z"] = 10, ["name"] = "default:wood"}, {["x"] = 1, ["y"] = 2, ["param1"] = 56, ["z"] = 11, ["name"] = "default:wood"}, {["x"] = 1, ["y"] = 2, ["param1"] = 56, ["z"] = 12, ["name"] = "default:wood"}, {["x"] = 1, ["y"] = 2, ["param1"] = 56, ["z"] = 13, ["name"] = "default:wood"}, {["x"] = 1, ["meta"] = {["fields"] = {}, ["inventory"] = {}}, ["y"] = 4, ["param1"] = 56, ["z"] = 2, ["name"] = "default:wood"}, {["x"] = 1, ["meta"] = {["fields"] = {}, ["inventory"] = {}}, ["y"] = 4, ["param1"] = 56, ["z"] = 3, ["name"] = "default:wood"}, {["x"] = 1, ["meta"] = {["fields"] = {}, ["inventory"] = {}}, ["y"] = 4, ["param1"] = 56, ["z"] = 4, ["name"] = "default:wood"}, {["x"] = 1, ["meta"] = {["fields"] = {}, ["inventory"] = {}}, ["y"] = 4, ["param1"] = 56, ["z"] = 5, ["name"] = "default:wood"}, {["x"] = 1, ["y"] = 10, ["param1"] = 76, ["z"] = 12, ["name"] = "wool:white"}, {["x"] = 1, ["y"] = 11, ["param1"] = 76, ["z"] = 12, ["name"] = "wool:white"}, {["x"] = 1, ["meta"] = {["fields"] = {}, ["inventory"] = {}}, ["y"] = 12, ["param1"] = 76, ["z"] = 3, ["name"] = "wool:white"}, {["x"] = 1, ["y"] = 12, ["param1"] = 76, ["z"] = 12, ["name"] = "wool:white"}, {["x"] = 1, ["meta"] = {["fields"] = {}, ["inventory"] = {}}, ["y"] = 13, ["param1"] = 76, ["z"] = 3, ["name"] = "wool:white"}, {["x"] = 1, ["y"] = 13, ["param1"] = 76, ["z"] = 12, ["name"] = "wool:white"}, {["x"] = 1, ["meta"] = {["fields"] = {}, ["inventory"] = {}}, ["y"] = 14, ["param1"] = 76, ["z"] = 3, ["name"] = "wool:white"}, {["x"] = 1, ["y"] = 14, ["param1"] = 76, ["z"] = 12, ["name"] = "wool:white"}, {["x"] = 1, ["y"] = 14, ["param1"] = 76, ["z"] = 15, ["name"] = "wool:white"}, {["x"] = 1, ["meta"] = {["fields"] = {}, ["inventory"] = {}}, ["y"] = 15, ["param1"] = 76, ["z"] = 3, ["name"] = "wool:white"}, {["x"] = 1, ["y"] = 15, ["param1"] = 76, ["z"] = 10, ["name"] = "wool:white"}, {["x"] = 1, ["y"] = 15, ["param1"] = 76, ["z"] = 11, ["name"] = "wool:white"}, {["x"] = 1, ["y"] = 15, ["param1"] = 76, ["z"] = 12, ["name"] = "wool:white"}, {["x"] = 1, ["y"] = 15, ["param1"] = 76, ["z"] = 13, ["name"] = "wool:white"}, {["x"] = 1, ["y"] = 15, ["param1"] = 76, ["z"] = 14, ["name"] = "wool:white"}, {["x"] = 1, ["meta"] = {["fields"] = {}, ["inventory"] = {}}, ["y"] = 16, ["param1"] = 76, ["z"] = 3, ["name"] = "wool:white"}, {["x"] = 1, ["meta"] = {["fields"] = {}, ["inventory"] = {}}, ["y"] = 16, ["param1"] = 76, ["z"] = 6, ["name"] = "wool:white"}, {["x"] = 1, ["meta"] = {["fields"] = {}, ["inventory"] = {}}, ["y"] = 16, ["param1"] = 76, ["z"] = 7, ["name"] = "wool:white"}, {["x"] = 1, ["y"] = 16, ["param1"] = 76, ["z"] = 8, ["name"] = "wool:white"}, {["x"] = 1, ["y"] = 16, ["param1"] = 76, ["z"] = 9, ["name"] = "wool:white"}, {["x"] = 1, ["meta"] = {["fields"] = {}, ["inventory"] = {}}, ["y"] = 17, ["param1"] = 76, ["z"] = 0, ["name"] = "wool:white"}, {["x"] = 1, ["meta"] = {["fields"] = {}, ["inventory"] = {}}, ["y"] = 17, ["param1"] = 76, ["z"] = 1, ["name"] = "wool:white"}, {["x"] = 1, ["meta"] = {["fields"] = {}, ["inventory"] = {}}, ["y"] = 17, ["param1"] = 76, ["z"] = 2, ["name"] = "wool:white"}, {["x"] = 1, ["meta"] = {["fields"] = {}, ["inventory"] = {}}, ["y"] = 17, ["param1"] = 76, ["z"] = 3, ["name"] = "wool:white"}, {["x"] = 1, ["meta"] = {["fields"] = {}, ["inventory"] = {}}, ["y"] = 17, ["param1"] = 76, ["z"] = 4, ["name"] = "wool:white"}, {["x"] = 1, ["meta"] = {["fields"] = {}, ["inventory"] = {}}, ["y"] = 17, ["param1"] = 76, ["z"] = 5, ["name"] = "wool:white"}, {["x"] = 2, ["y"] = 2, ["param1"] = 56, ["z"] = 10, ["name"] = "default:wood"}, {["x"] = 2, ["y"] = 2, ["param1"] = 56, ["z"] = 11, ["name"] = "default:wood"}, {["x"] = 2, ["y"] = 2, ["param1"] = 56, ["z"] = 12, ["name"] = "default:wood"}, {["x"] = 2, ["y"] = 2, ["param1"] = 56, ["z"] = 13, ["name"] = "default:wood"}, {["x"] = 2, ["meta"] = {["fields"] = {}, ["inventory"] = {}}, ["y"] = 4, ["param1"] = 56, ["z"] = 2, ["name"] = "default:wood"}, {["x"] = 2, ["meta"] = {["fields"] = {}, ["inventory"] = {}}, ["y"] = 4, ["param1"] = 56, ["z"] = 3, ["name"] = "default:wood"}, {["x"] = 2, ["meta"] = {["fields"] = {}, ["inventory"] = {}}, ["y"] = 4, ["param1"] = 56, ["z"] = 4, ["name"] = "default:wood"}, {["x"] = 2, ["meta"] = {["fields"] = {}, ["inventory"] = {}}, ["y"] = 4, ["param1"] = 56, ["z"] = 5, ["name"] = "default:wood"}, {["x"] = 2, ["y"] = 4, ["param1"] = 76, ["z"] = 12, ["name"] = "wool:white"}, {["x"] = 2, ["y"] = 5, ["param1"] = 76, ["z"] = 12, ["name"] = "wool:white"}, {["x"] = 2, ["meta"] = {["fields"] = {}, ["inventory"] = {}}, ["y"] = 6, ["param1"] = 76, ["z"] = 3, ["name"] = "wool:white"}, {["x"] = 2, ["y"] = 6, ["param1"] = 76, ["z"] = 12, ["name"] = "wool:white"}, {["x"] = 2, ["meta"] = {["fields"] = {}, ["inventory"] = {}}, ["y"] = 7, ["param1"] = 76, ["z"] = 3, ["name"] = "wool:white"}, {["x"] = 2, ["y"] = 7, ["param1"] = 76, ["z"] = 12, ["name"] = "wool:white"}, {["x"] = 2, ["meta"] = {["fields"] = {}, ["inventory"] = {}}, ["y"] = 8, ["param1"] = 76, ["z"] = 3, ["name"] = "wool:white"}, {["x"] = 2, ["y"] = 8, ["param1"] = 76, ["z"] = 12, ["name"] = "wool:white"}, {["x"] = 2, ["meta"] = {["fields"] = {}, ["inventory"] = {}}, ["y"] = 9, ["param1"] = 76, ["z"] = 3, ["name"] = "wool:white"}, {["x"] = 2, ["y"] = 9, ["param1"] = 76, ["z"] = 12, ["name"] = "wool:white"}, {["x"] = 2, ["meta"] = {["fields"] = {}, ["inventory"] = {}}, ["y"] = 10, ["param1"] = 76, ["z"] = 3, ["name"] = "wool:white"}, {["x"] = 2, ["meta"] = {["fields"] = {}, ["inventory"] = {}}, ["y"] = 11, ["param1"] = 76, ["z"] = 3, ["name"] = "wool:white"}, {["x"] = 2, ["y"] = 15, ["param1"] = 76, ["z"] = 12, ["name"] = "wool:white"}, {["x"] = 2, ["meta"] = {["fields"] = {}, ["inventory"] = {}}, ["y"] = 17, ["param1"] = 76, ["z"] = 3, ["name"] = "wool:white"}, {["x"] = 3, ["y"] = 1, ["param1"] = 76, ["z"] = 11, ["name"] = "wool:white"}, {["x"] = 3, ["y"] = 1, ["param1"] = 76, ["z"] = 12, ["name"] = "wool:white"}, {["x"] = 3, ["y"] = 1, ["param1"] = 76, ["z"] = 15, ["name"] = "wool:white"}, {["x"] = 3, ["y"] = 2, ["param1"] = 76, ["z"] = 9, ["name"] = "wool:white"}, {["x"] = 3, ["y"] = 2, ["param1"] = 76, ["z"] = 10, ["name"] = "wool:white"}, {["x"] = 3, ["y"] = 2, ["param1"] = 56, ["z"] = 11, ["name"] = "default:wood"}, {["x"] = 3, ["y"] = 2, ["param1"] = 56, ["z"] = 12, ["name"] = "default:wood"}, {["x"] = 3, ["y"] = 2, ["param1"] = 76, ["z"] = 13, ["name"] = "wool:white"}, {["x"] = 3, ["y"] = 2, ["param1"] = 76, ["z"] = 14, ["name"] = "wool:white"}, {["x"] = 3, ["meta"] = {["fields"] = {}, ["inventory"] = {}}, ["y"] = 3, ["param1"] = 76, ["z"] = 3, ["name"] = "wool:white"}, {["x"] = 3, ["meta"] = {["fields"] = {}, ["inventory"] = {}}, ["y"] = 3, ["param1"] = 76, ["z"] = 4, ["name"] = "wool:white"}, {["x"] = 3, ["meta"] = {["fields"] = {}, ["inventory"] = {}}, ["y"] = 3, ["param1"] = 76, ["z"] = 7, ["name"] = "wool:white"}, {["x"] = 3, ["y"] = 3, ["param1"] = 76, ["z"] = 8, ["name"] = "wool:white"}, {["x"] = 3, ["y"] = 3, ["param1"] = 76, ["z"] = 11, ["name"] = "wool:white"}, {["x"] = 3, ["y"] = 3, ["param1"] = 76, ["z"] = 12, ["name"] = "wool:white"}, {["x"] = 3, ["meta"] = {["fields"] = {}, ["inventory"] = {}}, ["y"] = 4, ["param1"] = 76, ["z"] = 0, ["name"] = "wool:white"}, {["x"] = 3, ["meta"] = {["fields"] = {}, ["inventory"] = {}}, ["y"] = 4, ["param1"] = 76, ["z"] = 1, ["name"] = "wool:white"}, {["x"] = 3, ["meta"] = {["fields"] = {}, ["inventory"] = {}}, ["y"] = 4, ["param1"] = 76, ["z"] = 2, ["name"] = "wool:white"}, {["x"] = 3, ["meta"] = {["fields"] = {}, ["inventory"] = {}}, ["y"] = 4, ["param1"] = 56, ["z"] = 3, ["name"] = "default:wood"}, {["x"] = 3, ["meta"] = {["fields"] = {}, ["inventory"] = {}}, ["y"] = 4, ["param1"] = 56, ["z"] = 4, ["name"] = "default:wood"}, {["x"] = 3, ["meta"] = {["fields"] = {}, ["inventory"] = {}}, ["y"] = 4, ["param1"] = 76, ["z"] = 5, ["name"] = "wool:white"}, {["x"] = 3, ["meta"] = {["fields"] = {}, ["inventory"] = {}}, ["y"] = 4, ["param1"] = 76, ["z"] = 6, ["name"] = "wool:white"}, {["x"] = 3, ["meta"] = {["fields"] = {}, ["inventory"] = {}}, ["y"] = 5, ["param1"] = 76, ["z"] = 3, ["name"] = "wool:white"}, {["x"] = 3, ["meta"] = {["fields"] = {}, ["inventory"] = {}}, ["y"] = 5, ["param1"] = 76, ["z"] = 4, ["name"] = "wool:white"}, {["x"] = 4, ["y"] = 2, ["param1"] = 56, ["z"] = 10, ["name"] = "default:wood"}, {["x"] = 4, ["y"] = 2, ["param1"] = 56, ["z"] = 11, ["name"] = "default:wood"}, {["x"] = 4, ["y"] = 2, ["param1"] = 56, ["z"] = 12, ["name"] = "default:wood"}, {["x"] = 4, ["y"] = 2, ["param1"] = 56, ["z"] = 13, ["name"] = "default:wood"}, {["x"] = 4, ["meta"] = {["fields"] = {}, ["inventory"] = {}}, ["y"] = 4, ["param1"] = 56, ["z"] = 2, ["name"] = "default:wood"}, {["x"] = 4, ["meta"] = {["fields"] = {}, ["inventory"] = {}}, ["y"] = 4, ["param1"] = 56, ["z"] = 3, ["name"] = "default:wood"}, {["x"] = 4, ["meta"] = {["fields"] = {}, ["inventory"] = {}}, ["y"] = 4, ["param1"] = 56, ["z"] = 4, ["name"] = "default:wood"}, {["x"] = 4, ["meta"] = {["fields"] = {}, ["inventory"] = {}}, ["y"] = 4, ["param1"] = 56, ["z"] = 5, ["name"] = "default:wood"}, {["x"] = 5, ["y"] = 2, ["param1"] = 56, ["z"] = 10, ["name"] = "default:wood"}, {["x"] = 5, ["y"] = 2, ["param1"] = 56, ["z"] = 11, ["name"] = "default:wood"}, {["x"] = 5, ["y"] = 2, ["param1"] = 56, ["z"] = 12, ["name"] = "default:wood"}, {["x"] = 5, ["y"] = 2, ["param1"] = 56, ["z"] = 13, ["name"] = "default:wood"}, {["x"] = 5, ["meta"] = {["fields"] = {}, ["inventory"] = {}}, ["y"] = 4, ["param1"] = 56, ["z"] = 2, ["name"] = "default:wood"}, {["x"] = 5, ["meta"] = {["fields"] = {}, ["inventory"] = {}}, ["y"] = 4, ["param1"] = 56, ["z"] = 3, ["name"] = "default:wood"}, {["x"] = 5, ["meta"] = {["fields"] = {}, ["inventory"] = {}}, ["y"] = 4, ["param1"] = 56, ["z"] = 4, ["name"] = "default:wood"}, {["x"] = 5, ["meta"] = {["fields"] = {}, ["inventory"] = {}}, ["y"] = 4, ["param1"] = 56, ["z"] = 5, ["name"] = "default:wood"}, {["x"] = 6, ["y"] = 2, ["param1"] = 56, ["z"] = 10, ["name"] = "default:wood"}, {["x"] = 6, ["y"] = 2, ["param1"] = 56, ["z"] = 11, ["name"] = "default:wood"}, {["x"] = 6, ["y"] = 2, ["param1"] = 56, ["z"] = 12, ["name"] = "default:wood"}, {["x"] = 6, ["y"] = 2, ["param1"] = 56, ["z"] = 13, ["name"] = "default:wood"}, {["x"] = 6, ["meta"] = {["fields"] = {}, ["inventory"] = {}}, ["y"] = 4, ["param1"] = 56, ["z"] = 2, ["name"] = "default:wood"}, {["x"] = 6, ["meta"] = {["fields"] = {}, ["inventory"] = {}}, ["y"] = 4, ["param1"] = 56, ["z"] = 3, ["name"] = "default:wood"}, {["x"] = 6, ["meta"] = {["fields"] = {}, ["inventory"] = {}}, ["y"] = 4, ["param1"] = 56, ["z"] = 4, ["name"] = "default:wood"}, {["x"] = 6, ["meta"] = {["fields"] = {}, ["inventory"] = {}}, ["y"] = 4, ["param1"] = 56, ["z"] = 5, ["name"] = "default:wood"}, {["x"] = 7, ["y"] = 2, ["param1"] = 56, ["z"] = 10, ["name"] = "default:wood"}, {["x"] = 7, ["y"] = 2, ["param1"] = 56, ["z"] = 11, ["name"] = "default:wood"}, {["x"] = 7, ["y"] = 2, ["param1"] = 56, ["z"] = 12, ["name"] = "default:wood"}, {["x"] = 7, ["y"] = 2, ["param1"] = 56, ["z"] = 13, ["name"] = "default:wood"}, {["x"] = 7, ["meta"] = {["fields"] = {}, ["inventory"] = {}}, ["y"] = 4, ["param1"] = 56, ["z"] = 2, ["name"] = "default:wood"}, {["x"] = 7, ["meta"] = {["fields"] = {}, ["inventory"] = {}}, ["y"] = 4, ["param1"] = 56, ["z"] = 3, ["name"] = "default:wood"}, {["x"] = 7, ["meta"] = {["fields"] = {}, ["inventory"] = {}}, ["y"] = 4, ["param1"] = 56, ["z"] = 4, ["name"] = "default:wood"}, {["x"] = 7, ["meta"] = {["fields"] = {}, ["inventory"] = {}}, ["y"] = 4, ["param1"] = 56, ["z"] = 5, ["name"] = "default:wood"}, {["x"] = 8, ["y"] = 2, ["param1"] = 56, ["z"] = 10, ["name"] = "default:wood"}, {["x"] = 8, ["y"] = 2, ["param1"] = 56, ["z"] = 11, ["name"] = "default:wood"}, {["x"] = 8, ["y"] = 2, ["param1"] = 56, ["z"] = 12, ["name"] = "default:wood"}, {["x"] = 8, ["y"] = 2, ["param1"] = 56, ["z"] = 13, ["name"] = "default:wood"}, {["x"] = 8, ["meta"] = {["fields"] = {}, ["inventory"] = {}}, ["y"] = 4, ["param1"] = 56, ["z"] = 2, ["name"] = "default:wood"}, {["x"] = 8, ["meta"] = {["fields"] = {}, ["inventory"] = {}}, ["y"] = 4, ["param1"] = 56, ["z"] = 3, ["name"] = "default:wood"}, {["x"] = 8, ["meta"] = {["fields"] = {}, ["inventory"] = {}}, ["y"] = 4, ["param1"] = 56, ["z"] = 4, ["name"] = "default:wood"}, {["x"] = 8, ["meta"] = {["fields"] = {}, ["inventory"] = {}}, ["y"] = 4, ["param1"] = 56, ["z"] = 5, ["name"] = "default:wood"}, {["x"] = 9, ["y"] = 2, ["param1"] = 56, ["z"] = 10, ["name"] = "default:wood"}, {["x"] = 9, ["y"] = 2, ["param1"] = 56, ["z"] = 11, ["name"] = "default:wood"}, {["x"] = 9, ["y"] = 2, ["param1"] = 56, ["z"] = 12, ["name"] = "default:wood"}, {["x"] = 9, ["y"] = 2, ["param1"] = 56, ["z"] = 13, ["name"] = "default:wood"}, {["x"] = 9, ["meta"] = {["fields"] = {}, ["inventory"] = {}}, ["y"] = 4, ["param1"] = 56, ["z"] = 2, ["name"] = "default:wood"}, {["x"] = 9, ["meta"] = {["fields"] = {}, ["inventory"] = {}}, ["y"] = 4, ["param1"] = 56, ["z"] = 3, ["name"] = "default:wood"}, {["x"] = 9, ["meta"] = {["fields"] = {}, ["inventory"] = {}}, ["y"] = 4, ["param1"] = 56, ["z"] = 4, ["name"] = "default:wood"}, {["x"] = 9, ["meta"] = {["fields"] = {}, ["inventory"] = {}}, ["y"] = 4, ["param1"] = 56, ["z"] = 5, ["name"] = "default:wood"}, {["x"] = 10, ["y"] = 2, ["param1"] = 56, ["z"] = 10, ["name"] = "default:wood"}, {["x"] = 10, ["y"] = 2, ["param1"] = 56, ["z"] = 11, ["name"] = "default:wood"}, {["x"] = 10, ["y"] = 2, ["param1"] = 56, ["z"] = 12, ["name"] = "default:wood"}, {["x"] = 10, ["y"] = 2, ["param1"] = 56, ["z"] = 13, ["name"] = "default:wood"}, {["x"] = 10, ["meta"] = {["fields"] = {}, ["inventory"] = {}}, ["y"] = 4, ["param1"] = 56, ["z"] = 2, ["name"] = "default:wood"}, {["x"] = 10, ["meta"] = {["fields"] = {}, ["inventory"] = {}}, ["y"] = 4, ["param1"] = 56, ["z"] = 3, ["name"] = "default:wood"}, {["x"] = 10, ["meta"] = {["fields"] = {}, ["inventory"] = {}}, ["y"] = 4, ["param1"] = 56, ["z"] = 4, ["name"] = "default:wood"}, {["x"] = 10, ["meta"] = {["fields"] = {}, ["inventory"] = {}}, ["y"] = 4, ["param1"] = 56, ["z"] = 5, ["name"] = "default:wood"}, {["x"] = 11, ["y"] = 2, ["param1"] = 56, ["z"] = 10, ["name"] = "default:wood"}, {["x"] = 11, ["y"] = 2, ["param1"] = 56, ["z"] = 11, ["name"] = "default:wood"}, {["x"] = 11, ["y"] = 2, ["param1"] = 56, ["z"] = 12, ["name"] = "default:wood"}, {["x"] = 11, ["y"] = 2, ["param1"] = 56, ["z"] = 13, ["name"] = "default:wood"}, {["x"] = 11, ["meta"] = {["fields"] = {}, ["inventory"] = {}}, ["y"] = 4, ["param1"] = 56, ["z"] = 2, ["name"] = "default:wood"}, {["x"] = 11, ["meta"] = {["fields"] = {}, ["inventory"] = {}}, ["y"] = 4, ["param1"] = 56, ["z"] = 3, ["name"] = "default:wood"}, {["x"] = 11, ["meta"] = {["fields"] = {}, ["inventory"] = {}}, ["y"] = 4, ["param1"] = 56, ["z"] = 4, ["name"] = "default:wood"}, {["x"] = 11, ["meta"] = {["fields"] = {}, ["inventory"] = {}}, ["y"] = 4, ["param1"] = 56, ["z"] = 5, ["name"] = "default:wood"}, {["x"] = 12, ["y"] = 1, ["param1"] = 76, ["z"] = 11, ["name"] = "wool:white"}, {["x"] = 12, ["y"] = 1, ["param1"] = 76, ["z"] = 12, ["name"] = "wool:white"}, {["x"] = 12, ["y"] = 1, ["param1"] = 76, ["z"] = 15, ["name"] = "wool:white"}, {["x"] = 12, ["y"] = 2, ["param1"] = 76, ["z"] = 9, ["name"] = "wool:white"}, {["x"] = 12, ["y"] = 2, ["param1"] = 76, ["z"] = 10, ["name"] = "wool:white"}, {["x"] = 12, ["y"] = 2, ["param1"] = 56, ["z"] = 11, ["name"] = "default:wood"}, {["x"] = 12, ["y"] = 2, ["param1"] = 56, ["z"] = 12, ["name"] = "default:wood"}, {["x"] = 12, ["y"] = 2, ["param1"] = 76, ["z"] = 13, ["name"] = "wool:white"}, {["x"] = 12, ["y"] = 2, ["param1"] = 76, ["z"] = 14, ["name"] = "wool:white"}, {["x"] = 12, ["meta"] = {["fields"] = {}, ["inventory"] = {}}, ["y"] = 3, ["param1"] = 76, ["z"] = 3, ["name"] = "wool:white"}, {["x"] = 12, ["meta"] = {["fields"] = {}, ["inventory"] = {}}, ["y"] = 3, ["param1"] = 76, ["z"] = 4, ["name"] = "wool:white"}, {["x"] = 12, ["meta"] = {["fields"] = {}, ["inventory"] = {}}, ["y"] = 3, ["param1"] = 76, ["z"] = 7, ["name"] = "wool:white"}, {["x"] = 12, ["y"] = 3, ["param1"] = 76, ["z"] = 8, ["name"] = "wool:white"}, {["x"] = 12, ["y"] = 3, ["param1"] = 76, ["z"] = 11, ["name"] = "wool:white"}, {["x"] = 12, ["y"] = 3, ["param1"] = 76, ["z"] = 12, ["name"] = "wool:white"}, {["x"] = 12, ["meta"] = {["fields"] = {}, ["inventory"] = {}}, ["y"] = 4, ["param1"] = 76, ["z"] = 0, ["name"] = "wool:white"}, {["x"] = 12, ["meta"] = {["fields"] = {}, ["inventory"] = {}}, ["y"] = 4, ["param1"] = 76, ["z"] = 1, ["name"] = "wool:white"}, {["x"] = 12, ["meta"] = {["fields"] = {}, ["inventory"] = {}}, ["y"] = 4, ["param1"] = 76, ["z"] = 2, ["name"] = "wool:white"}, {["x"] = 12, ["meta"] = {["fields"] = {}, ["inventory"] = {}}, ["y"] = 4, ["param1"] = 56, ["z"] = 3, ["name"] = "default:wood"}, {["x"] = 12, ["meta"] = {["fields"] = {}, ["inventory"] = {}}, ["y"] = 4, ["param1"] = 56, ["z"] = 4, ["name"] = "default:wood"}, {["x"] = 12, ["meta"] = {["fields"] = {}, ["inventory"] = {}}, ["y"] = 4, ["param1"] = 76, ["z"] = 5, ["name"] = "wool:white"}, {["x"] = 12, ["meta"] = {["fields"] = {}, ["inventory"] = {}}, ["y"] = 4, ["param1"] = 76, ["z"] = 6, ["name"] = "wool:white"}, {["x"] = 12, ["meta"] = {["fields"] = {}, ["inventory"] = {}}, ["y"] = 5, ["param1"] = 76, ["z"] = 3, ["name"] = "wool:white"}, {["x"] = 12, ["meta"] = {["fields"] = {}, ["inventory"] = {}}, ["y"] = 5, ["param1"] = 76, ["z"] = 4, ["name"] = "wool:white"}, {["x"] = 13, ["y"] = 2, ["param1"] = 56, ["z"] = 10, ["name"] = "default:wood"}, {["x"] = 13, ["y"] = 2, ["param1"] = 56, ["z"] = 11, ["name"] = "default:wood"}, {["x"] = 13, ["y"] = 2, ["param1"] = 56, ["z"] = 12, ["name"] = "default:wood"}, {["x"] = 13, ["y"] = 2, ["param1"] = 56, ["z"] = 13, ["name"] = "default:wood"}, {["x"] = 13, ["meta"] = {["fields"] = {}, ["inventory"] = {}}, ["y"] = 4, ["param1"] = 56, ["z"] = 2, ["name"] = "default:wood"}, {["x"] = 13, ["meta"] = {["fields"] = {}, ["inventory"] = {}}, ["y"] = 4, ["param1"] = 56, ["z"] = 3, ["name"] = "default:wood"}, {["x"] = 13, ["meta"] = {["fields"] = {}, ["inventory"] = {}}, ["y"] = 4, ["param1"] = 56, ["z"] = 4, ["name"] = "default:wood"}, {["x"] = 13, ["meta"] = {["fields"] = {}, ["inventory"] = {}}, ["y"] = 4, ["param1"] = 56, ["z"] = 5, ["name"] = "default:wood"}, {["x"] = 13, ["y"] = 4, ["param1"] = 76, ["z"] = 12, ["name"] = "wool:white"}, {["x"] = 13, ["y"] = 5, ["param1"] = 76, ["z"] = 12, ["name"] = "wool:white"}, {["x"] = 13, ["meta"] = {["fields"] = {}, ["inventory"] = {}}, ["y"] = 6, ["param1"] = 76, ["z"] = 3, ["name"] = "wool:white"}, {["x"] = 13, ["y"] = 6, ["param1"] = 76, ["z"] = 12, ["name"] = "wool:white"}, {["x"] = 13, ["meta"] = {["fields"] = {}, ["inventory"] = {}}, ["y"] = 7, ["param1"] = 76, ["z"] = 3, ["name"] = "wool:white"}, {["x"] = 13, ["y"] = 7, ["param1"] = 76, ["z"] = 12, ["name"] = "wool:white"}, {["x"] = 13, ["meta"] = {["fields"] = {}, ["inventory"] = {}}, ["y"] = 8, ["param1"] = 76, ["z"] = 3, ["name"] = "wool:white"}, {["x"] = 13, ["y"] = 8, ["param1"] = 76, ["z"] = 12, ["name"] = "wool:white"}, {["x"] = 13, ["meta"] = {["fields"] = {}, ["inventory"] = {}}, ["y"] = 9, ["param1"] = 76, ["z"] = 3, ["name"] = "wool:white"}, {["x"] = 13, ["y"] = 9, ["param1"] = 76, ["z"] = 12, ["name"] = "wool:white"}, {["x"] = 13, ["meta"] = {["fields"] = {}, ["inventory"] = {}}, ["y"] = 10, ["param1"] = 76, ["z"] = 3, ["name"] = "wool:white"}, {["x"] = 13, ["meta"] = {["fields"] = {}, ["inventory"] = {}}, ["y"] = 11, ["param1"] = 76, ["z"] = 3, ["name"] = "wool:white"}, {["x"] = 13, ["y"] = 15, ["param1"] = 76, ["z"] = 12, ["name"] = "wool:white"}, {["x"] = 13, ["meta"] = {["fields"] = {}, ["inventory"] = {}}, ["y"] = 17, ["param1"] = 76, ["z"] = 3, ["name"] = "wool:white"}, {["x"] = 14, ["y"] = 2, ["param1"] = 56, ["z"] = 10, ["name"] = "default:wood"}, {["x"] = 14, ["y"] = 2, ["param1"] = 56, ["z"] = 11, ["name"] = "default:wood"}, {["x"] = 14, ["y"] = 2, ["param1"] = 56, ["z"] = 12, ["name"] = "default:wood"}, {["x"] = 14, ["y"] = 2, ["param1"] = 56, ["z"] = 13, ["name"] = "default:wood"}, {["x"] = 14, ["meta"] = {["fields"] = {}, ["inventory"] = {}}, ["y"] = 4, ["param1"] = 56, ["z"] = 2, ["name"] = "default:wood"}, {["x"] = 14, ["meta"] = {["fields"] = {}, ["inventory"] = {}}, ["y"] = 4, ["param1"] = 56, ["z"] = 3, ["name"] = "default:wood"}, {["x"] = 14, ["meta"] = {["fields"] = {}, ["inventory"] = {}}, ["y"] = 4, ["param1"] = 56, ["z"] = 4, ["name"] = "default:wood"}, {["x"] = 14, ["meta"] = {["fields"] = {}, ["inventory"] = {}}, ["y"] = 4, ["param1"] = 56, ["z"] = 5, ["name"] = "default:wood"}, {["x"] = 14, ["y"] = 10, ["param1"] = 76, ["z"] = 12, ["name"] = "wool:white"}, {["x"] = 14, ["y"] = 11, ["param1"] = 76, ["z"] = 12, ["name"] = "wool:white"}, {["x"] = 14, ["meta"] = {["fields"] = {}, ["inventory"] = {}}, ["y"] = 12, ["param1"] = 76, ["z"] = 3, ["name"] = "wool:white"}, {["x"] = 14, ["y"] = 12, ["param1"] = 76, ["z"] = 12, ["name"] = "wool:white"}, {["x"] = 14, ["meta"] = {["fields"] = {}, ["inventory"] = {}}, ["y"] = 13, ["param1"] = 76, ["z"] = 3, ["name"] = "wool:white"}, {["x"] = 14, ["y"] = 13, ["param1"] = 76, ["z"] = 12, ["name"] = "wool:white"}, {["x"] = 14, ["meta"] = {["fields"] = {}, ["inventory"] = {}}, ["y"] = 14, ["param1"] = 76, ["z"] = 3, ["name"] = "wool:white"}, {["x"] = 14, ["y"] = 14, ["param1"] = 76, ["z"] = 12, ["name"] = "wool:white"}, {["x"] = 14, ["y"] = 14, ["param1"] = 76, ["z"] = 15, ["name"] = "wool:white"}, {["x"] = 14, ["meta"] = {["fields"] = {}, ["inventory"] = {}}, ["y"] = 15, ["param1"] = 76, ["z"] = 3, ["name"] = "wool:white"}, {["x"] = 14, ["y"] = 15, ["param1"] = 76, ["z"] = 10, ["name"] = "wool:white"}, {["x"] = 14, ["y"] = 15, ["param1"] = 76, ["z"] = 11, ["name"] = "wool:white"}, {["x"] = 14, ["y"] = 15, ["param1"] = 76, ["z"] = 12, ["name"] = "wool:white"}, {["x"] = 14, ["y"] = 15, ["param1"] = 76, ["z"] = 13, ["name"] = "wool:white"}, {["x"] = 14, ["y"] = 15, ["param1"] = 76, ["z"] = 14, ["name"] = "wool:white"}, {["x"] = 14, ["meta"] = {["fields"] = {}, ["inventory"] = {}}, ["y"] = 16, ["param1"] = 76, ["z"] = 3, ["name"] = "wool:white"}, {["x"] = 14, ["meta"] = {["fields"] = {}, ["inventory"] = {}}, ["y"] = 16, ["param1"] = 76, ["z"] = 6, ["name"] = "wool:white"}, {["x"] = 14, ["meta"] = {["fields"] = {}, ["inventory"] = {}}, ["y"] = 16, ["param1"] = 76, ["z"] = 7, ["name"] = "wool:white"}, {["x"] = 14, ["y"] = 16, ["param1"] = 76, ["z"] = 8, ["name"] = "wool:white"}, {["x"] = 14, ["y"] = 16, ["param1"] = 76, ["z"] = 9, ["name"] = "wool:white"}, {["x"] = 14, ["meta"] = {["fields"] = {}, ["inventory"] = {}}, ["y"] = 17, ["param1"] = 76, ["z"] = 0, ["name"] = "wool:white"}, {["x"] = 14, ["meta"] = {["fields"] = {}, ["inventory"] = {}}, ["y"] = 17, ["param1"] = 76, ["z"] = 1, ["name"] = "wool:white"}, {["x"] = 14, ["meta"] = {["fields"] = {}, ["inventory"] = {}}, ["y"] = 17, ["param1"] = 76, ["z"] = 2, ["name"] = "wool:white"}, {["x"] = 14, ["meta"] = {["fields"] = {}, ["inventory"] = {}}, ["y"] = 17, ["param1"] = 76, ["z"] = 3, ["name"] = "wool:white"}, {["x"] = 14, ["meta"] = {["fields"] = {}, ["inventory"] = {}}, ["y"] = 17, ["param1"] = 76, ["z"] = 4, ["name"] = "wool:white"}, {["x"] = 14, ["meta"] = {["fields"] = {}, ["inventory"] = {}}, ["y"] = 17, ["param1"] = 76, ["z"] = 5, ["name"] = "wool:white"}, {["x"] = 15, ["y"] = 15, ["param1"] = 76, ["z"] = 12, ["name"] = "wool:white"}, {["x"] = 15, ["meta"] = {["fields"] = {}, ["inventory"] = {}}, ["y"] = 16, ["param1"] = 76, ["z"] = 3, ["name"] = "wool:white"}}